<?xml version="1.0" encoding="utf-8"?>
<!-- This URDF was automatically created by SolidWorks to URDF Exporter! Originally created by Stephen Brawner (brawner@gmail.com) 
     Commit Version: 1.6.0-4-g7f85cfe  Build Version: 1.6.7995.38578
     For more information, please see http://wiki.ros.org/sw_urdf_exporter -->
<robot
  name="X7leftA">
  <link
    name="base_link">
    <inertial>
      <origin
        xyz="1.2504E-08 0.028434 0.00042549"
        rpy="0 0 0" />
      <mass
        value="0.41722" />
      <inertia
        ixx="0.00019"
        ixy="0.00000"
        ixz="0.00000"
        iyy="0.00020"
        iyz="0.00000"
        izz="0.00019" />
    </inertial>
    <visual>
      <origin
        xyz="0 0 0"
        rpy="0 0 0" />
      <geometry>
        <mesh
          filename="package://X7leftA/meshes/base_link.STL" />
      </geometry>
      <material
        name="">
        <color
          rgba="0.89804 0.91765 0.92941 1" />
      </material>
    </visual>
    <collision>
      <origin
        xyz="0 0 0"
        rpy="0 0 0" />
      <geometry>
        <mesh
          filename="package://X7leftA/meshes/base_link.STL" />
      </geometry>
    </collision>
  </link>
  <link
    name="link1">
    <inertial>
      <origin
        xyz="0.020311877665791 0.0282074621926083 -0.000172803675324382"
        rpy="0 0 0" />
      <mass
        value="0.131891884746085" />
      <inertia
        ixx="0.00012"
        ixy="0.00004"
        ixz="0.00000"
        iyy="0.00009"
        iyz="0.00000"
        izz="0.00014" />
    </inertial>
    <visual>
      <origin
        xyz="0 0 0"
        rpy="0 0 0" />
      <geometry>
        <mesh
          filename="package://X7leftA/meshes/link1.STL" />
      </geometry>
      <material
        name="">
        <color
          rgba="0.898039215686275 0.917647058823529 0.929411764705882 1" />
      </material>
    </visual>
    <collision>
      <origin
        xyz="0 0 0"
        rpy="0 0 0" />
      <geometry>
        <mesh
          filename="package://X7leftA/meshes/link1.STL" />
      </geometry>
    </collision>
  </link>
  <joint
    name="joint1"
    type="revolute">
    <origin
      xyz="0 0.05315 0"
      rpy="0 0 0" />
    <parent
      link="base_link" />
    <child
      link="link1" />
    <axis
      xyz="0 1 0" />
    <limit
      lower="-10"
      upper="10"
      effort="100"
      velocity="1000" />
  </joint>
  <link
    name="link2">
    <inertial>
      <origin
        xyz="0.0247335917011989 -0.00274560185380487 -0.027134395786836"
        rpy="0 0 0" />
      <mass
        value="0.971762138327377" />
      <inertia
        ixx="0.00153"
        ixy="0.00002"
        ixz="-0.00007"
        iyy="0.00153"
        iyz="-0.00002"
        izz="0.00074" />
    </inertial>
    <visual>
      <origin
        xyz="0 0 0"
        rpy="0 0 0" />
      <geometry>
        <mesh
          filename="package://X7leftA/meshes/link2.STL" />
      </geometry>
      <material
        name="">
        <color
          rgba="1 1 1 1" />
      </material>
    </visual>
    <collision>
      <origin
        xyz="0 0 0"
        rpy="0 0 0" />
      <geometry>
        <mesh
          filename="package://X7leftA/meshes/link2.STL" />
      </geometry>
    </collision>
  </link>
  <joint
    name="joint2"
    type="revolute">
    <origin
      xyz="0.02725 0.063 0"
      rpy="0 0 3.1416" />
    <parent
      link="link1" />
    <child
      link="link2" />
    <axis
      xyz="1 0 0" />
    <limit
      lower="-10"
      upper="10"
      effort="100"
      velocity="1000" />
  </joint>
  <link
    name="link3">
    <inertial>
      <origin
        xyz="-0.000221571129409272 0.00055401047728823 0.154388906739316"
        rpy="0 0 0" />
      <mass
        value="0.868202345580011" />
      <inertia
        ixx="0.00529"
        ixy="-0.00001"
        ixz="-0.00005"
        iyy="0.00553"
        iyz="0.00003"
        izz="0.00078" />
    </inertial>
    <visual>
      <origin
        xyz="0 0 0"
        rpy="0 0 0" />
      <geometry>
        <mesh
          filename="package://X7leftA/meshes/link3.STL" />
      </geometry>
      <material
        name="">
        <color
          rgba="1 1 1 1" />
      </material>
    </visual>
    <collision>
      <origin
        xyz="0 0 0"
        rpy="0 0 0" />
      <geometry>
        <mesh
          filename="package://X7leftA/meshes/link3.STL" />
      </geometry>
    </collision>
  </link>
  <joint
    name="joint3"
    type="revolute">
    <origin
      xyz="0.02725 0 -0.0885"
      rpy="-3.1416 0 -3.1416" />
    <parent
      link="link2" />
    <child
      link="link3" />
    <axis
      xyz="0 0 1" />
    <limit
      lower="-10"
      upper="10"
      effort="100"
      velocity="1000" />
  </joint>
  <link
    name="link4">
    <inertial>
      <origin
        xyz="0.0609931749498278 -0.0243615233623463 3.20631404896465E-05"
        rpy="0 0 0" />
      <mass
        value="0.483750765199191" />
      <inertia
        ixx="0.00037"
        ixy="-0.00001"
        ixz="0.00000"
        iyy="0.00043"
        iyz="0.00000"
        izz="0.00058" />
    </inertial>
    <visual>
      <origin
        xyz="0 0 0"
        rpy="0 0 0" />
      <geometry>
        <mesh
          filename="package://X7leftA/meshes/link4.STL" />
      </geometry>
      <material
        name="">
        <color
          rgba="0.898039215686275 0.917647058823529 0.929411764705882 1" />
      </material>
    </visual>
    <collision>
      <origin
        xyz="0 0 0"
        rpy="0 0 0" />
      <geometry>
        <mesh
          filename="package://X7leftA/meshes/link4.STL" />
      </geometry>
    </collision>
  </link>
  <joint
    name="joint4"
    type="revolute">
    <origin
      xyz="0 0.02625 0.2145"
      rpy="0 0 0" />
    <parent
      link="link3" />
    <child
      link="link4" />
    <axis
      xyz="0 1 0" />
    <limit
      lower="-10"
      upper="10"
      effort="100"
      velocity="1000" />
  </joint>
  <link
    name="link5">
    <inertial>
      <origin
        xyz="0.0527279325382702 -0.00868845688291262 -2.92074355756067E-05"
        rpy="0 0 0" />
      <mass
        value="0.585542044845075" />
      <inertia
        ixx="0.00058"
        ixy="0.00007"
        ixz="0.00000"
        iyy="0.00093"
        iyz="0.00000"
        izz="0.00108" />
    </inertial>
    <visual>
      <origin
        xyz="0 0 0"
        rpy="0 0 0" />
      <geometry>
        <mesh
          filename="package://X7leftA/meshes/link5.STL" />
      </geometry>
      <material
        name="">
        <color
          rgba="1 1 1 1" />
      </material>
    </visual>
    <collision>
      <origin
        xyz="0 0 0"
        rpy="0 0 0" />
      <geometry>
        <mesh
          filename="package://X7leftA/meshes/link5.STL" />
      </geometry>
    </collision>
  </link>
  <joint
    name="joint5"
    type="revolute">
    <origin
      xyz="0.0935 -0.02625 0"
      rpy="-3.1416 0 0" />
    <parent
      link="link4" />
    <child
      link="link5" />
    <axis
      xyz="1 0 0" />
    <limit
      lower="-10"
      upper="10"
      effort="100"
      velocity="1000" />
  </joint>
  <link
    name="link6">
    <inertial>
      <origin
        xyz="-4.56578061923674E-05 -0.0392589323429183 0.00112421819005831"
        rpy="0 0 0" />
      <mass
        value="0.339715469407624" />
      <inertia
        ixx="0.00014"
        ixy="0.00000"
        ixz="0.00000"
        iyy="0.00012"
        iyz="0.00000"
        izz="0.00016" />
    </inertial>
    <visual>
      <origin
        xyz="0 0 0"
        rpy="0 0 0" />
      <geometry>
        <mesh
          filename="package://X7leftA/meshes/link6.STL" />
      </geometry>
      <material
        name="">
        <color
          rgba="0.792156862745098 0.819607843137255 0.933333333333333 1" />
      </material>
    </visual>
    <collision>
      <origin
        xyz="0 0 0"
        rpy="0 0 0" />
      <geometry>
        <mesh
          filename="package://X7leftA/meshes/link6.STL" />
      </geometry>
    </collision>
  </link>
  <joint
    name="joint6"
    type="revolute">
    <origin
      xyz="0.1615 -0.04025 0"
      rpy="-3.1416 0 0" />
    <parent
      link="link5" />
    <child
      link="link6" />
    <axis
      xyz="0 1 0" />
    <limit
      lower="-10"
      upper="10"
      effort="100"
      velocity="1000" />
  </joint>
  <link
    name="link7">
    <inertial>
      <origin
        xyz="0.0904376753475253 -4.59300094023118E-05 0.0203282088603868"
        rpy="0 0 0" />
      <mass
        value="0.600472510680938" />
      <inertia
        ixx="0.00049"
        ixy="0.00000"
        ixz="0.00008"
        iyy="0.00078"
        iyz="0.00000"
        izz="0.00102" />
    </inertial>
    <visual>
      <origin
        xyz="0 0 0"
        rpy="0 0 0" />
      <geometry>
        <mesh
          filename="package://X7leftA/meshes/link7.STL" />
      </geometry>
      <material
        name="">
        <color
          rgba="0.792156862745098 0.819607843137255 0.933333333333333 1" />
      </material>
    </visual>
    <collision>
      <origin
        xyz="0 0 0"
        rpy="0 0 0" />
      <geometry>
        <mesh
          filename="package://X7leftA/meshes/link7.STL" />
      </geometry>
    </collision>
  </link>
  <joint
    name="joint7"
    type="revolute">
    <origin
      xyz="0 -0.04025 0.022"
      rpy="3.1416 0 0" />
    <parent
      link="link6" />
    <child
      link="link7" />
    <axis
      xyz="0 0 -1" />
    <limit
      lower="-10"
      upper="10"
      effort="100"
      velocity="1000" />
  </joint>
</robot>